<?xml version="1.0"?>
<robot name="ALEX" xmlns:xacro="http://ros.org/wiki/xacro">
  <xacro:property name="o_base_to_hip_x" value="0" />
  <xacro:property name="o_base_to_hip_y" value="-0.5" />
  <xacro:property name="o_base_to_hip_z" value="-0.1" />
  <xacro:property name="o_hip_to_knee_x" value="0.1" />
  <xacro:property name="o_hip_to_knee_y" value="0.1" />
  <xacro:property name="o_hip_to_knee_z" value="0.1" />
  <xacro:property name="l_knee_a" value="0.1" />
  <xacro:property name="l_knee_b" value="0.3" />
  <xacro:property name="l_shin_a" value="0.309" />
  <xacro:property name="l_shin_b" value="0.305" />
  <xacro:property name="l_shin_connection" value="0.115" />
  <xacro:property name="l_ankle_connection" value="0.07475" />
  <xacro:property name="l_ankle_a" value="0.02735" />
  <xacro:property name="l_ankle_b" value="0.0432" />
  <xacro:property name="l_ankle_c1" value="0.1493" />
  <xacro:property name="l_ankle_c2" value="0.155795" />
  <xacro:property name="l_foot_a" value="0.055" />
  <xacro:property name="l_foot_b" value="0.055" />

  <material name="red">
    <color rgba="1 0 0 1"/>
  </material>

  <material name="green">
    <color rgba="0 1 0 1"/>
  </material>

  <material name="blue">
    <color rgba="0 0 1 1"/>
  </material>

  <material name="yellow">
    <color rgba="1 1 0 1"/>
  </material>

  <material name="silver">
    <color rgba="0.73 0.73 0.73 1"/>
  </material>

  <material name="black">
    <color rgba="0 0 0 1"/>
  </material>

  <material name="white">
    <color rgba="1 1 1 1"/>
  </material>

  <xacro:macro name="leg" params="prefix reflect">
    <link name="${prefix}_hip_link">

    </link>
    <joint name="base_link_to_${prefix}_hip_link" type="continuous">
      <parent link="base_link"/>
      <child link="${prefix}_hip_link"/>
      <axis rpy="0 0 0" xyz="0 0 1"/>
      <origin rpy="0 ${pi/2} ${pi}" xyz="${o_base_to_hip_x} ${reflect * o_base_to_hip_y} ${o_base_to_hip_z}"/>
    </joint>

    <link name="${prefix}_knee_link_b">
      <visual>
        <geometry>
          <cylinder length="${l_knee_b}" radius="0.003"/>
        </geometry>
        <origin rpy="0 ${pi/2} 0" xyz="${l_knee_b/2} 0 0"/>
        <material name="blue"/>
      </visual>
    </link>
    <joint name="${prefix}_hip_link_to_${prefix}_knee_link_b" type="continuous">
      <parent link="${prefix}_hip_link"/>
      <child link="${prefix}_knee_link_b"/>
      <axis rpy="0 0 0" xyz="0 0 1"/>
      <origin rpy="${pi/2} ${-pi/4} 0" xyz="${o_hip_to_knee_x} ${reflect * o_hip_to_knee_y} ${o_hip_to_knee_z}"/>
    </joint>

    <link name="${prefix}_shin_link_b">
      <visual>
        <geometry>
          <cylinder length="${l_shin_b}" radius="0.003"/>
        </geometry>
        <origin rpy="0 ${pi/2} 0" xyz="${l_shin_b/2} 0 0"/>
        <material name="blue"/>
      </visual>
    </link>
    <joint name="${prefix}_knee_link_b_to_${prefix}_shin_link_b" type="continuous">
      <parent link="${prefix}_knee_link_b"/>
      <child link="${prefix}_shin_link_b"/>
      <axis rpy="0 0 0" xyz="0 0 1"/>
      <origin rpy="0 0 ${-pi/2}" xyz="${l_knee_b} 0 0"/>
    </joint>

    <link name="${prefix}_knee_link_a">
      <visual>
        <geometry>
          <cylinder length="${l_knee_a}" radius="0.003"/>
        </geometry>
        <origin rpy="0 ${pi/2} 0" xyz="${l_knee_a/2} 0 0"/>
        <material name="blue"/>
      </visual>
    </link>
    <joint name="${prefix}_knee_link_b_to_${prefix}_knee_link_a" type="continuous">
      <parent link="${prefix}_knee_link_b"/>
      <child link="${prefix}_knee_link_a"/>
      <axis rpy="0 0 0" xyz="0 0 1"/>
      <origin rpy="0 0 ${-pi/2}" xyz="0 0 0"/>
    </joint>

    <link name="${prefix}_shin_link_a">
      <visual>
        <geometry>
          <cylinder length="${l_shin_a}" radius="0.003"/>
        </geometry>
        <origin rpy="0 ${pi/2} 0" xyz="${l_shin_a/2} 0 0"/>
        <material name="blue"/>
      </visual>
    </link>
    <joint name="${prefix}_knee_link_a_to_${prefix}_shin_link_a" type="continuous">
      <parent link="${prefix}_knee_link_a"/>
      <child link="${prefix}_shin_link_a"/>
      <axis rpy="0 0 0" xyz="0 0 1"/>
      <origin rpy="0 0 ${pi/2}" xyz="${l_knee_a} 0 0"/>
    </joint>

    <link name="${prefix}_shin_link_connection">
      <visual>
        <geometry>
          <cylinder length="0" radius="0.003"/>
        </geometry>
        <origin rpy="0 ${pi/2} 0" xyz="${l_shin_connection/2} 0 0"/>
        <material name="blue"/>
      </visual>
    </link>
    <joint name="${prefix}_shink_link_b_to_${prefix}_shin_link_connection" type="continuous">
      <parent link="${prefix}_shin_link_b"/>
      <child link="${prefix}_shin_link_connection"/>
      <axis rpy="0 0 0" xyz="0 0 1"/>
      <origin rpy="0 0 0" xyz="${l_shin_connection} 0 0"/>
    </joint>

    <link name="${prefix}_foot_link_b">
      <visual>
        <geometry>
          <cylinder length="${l_foot_b}" radius="0.003"/>
        </geometry>
        <origin rpy="0 ${pi/2} 0" xyz="${l_foot_b/2} 0 0"/>
        <material name="blue"/>
      </visual>
    </link>
    <joint name="${prefix}_shin_link_connection_to_${prefix}_foot_link_b" type="continuous">
      <parent link="${prefix}_shin_link_connection"/>
      <child link="${prefix}_foot_link_b"/>
      <axis rpy="0 0 0" xyz="0 0 1"/>
      <origin rpy="0 0 ${-pi/2}" xyz="${l_shin_a - l_shin_connection} 0 0"/>
    </joint>

    <link name="${prefix}_ankle_link_a">
      <visual>
        <geometry>
          <cylinder length="${l_ankle_a}" radius="0.003"/>
        </geometry>
        <origin rpy="0 ${pi/2} 0" xyz="${l_ankle_a/2} 0 0"/>
        <material name="blue"/>
      </visual>
    </link>
    <joint name="${prefix}_shin_link_b_to_${prefix}_ankle_link_a" type="continuous">
      <parent link="${prefix}_shin_link_b"/>
      <child link="${prefix}_ankle_link_a"/>
      <axis rpy="0 0 0" xyz="0 0 1"/>
      <origin rpy="0 0 ${pi/2}" xyz="${l_ankle_connection} 0 0"/>
    </joint>

    <link name="${prefix}_ankle_link_b">
      <visual>
        <geometry>
          <cylinder length="${l_ankle_b}" radius="0.003"/>
        </geometry>
        <origin rpy="0 ${pi/2} 0" xyz="${l_ankle_b/2} 0 0"/>
        <material name="blue"/>
      </visual>
    </link>
    <joint name="${prefix}_ankle_link_a_to_${prefix}_ankle_link_b" type="continuous">
      <parent link="${prefix}_ankle_link_a"/>
      <child link="${prefix}_ankle_link_b"/>
      <axis rpy="0 0 0" xyz="0 0 1"/>
      <origin rpy="0 0 ${-pi/8}" xyz="${l_ankle_a} 0 0"/>
    </joint>

    <link name="${prefix}_ankle_link_c_1">
      <visual>
        <geometry>
          <cylinder length="${l_ankle_c1}" radius="0.003"/>
        </geometry>
        <origin rpy="0 ${pi/2} 0" xyz="${l_ankle_c1/2} 0 0"/>
        <material name="blue"/>
      </visual>
    </link>
    <joint name="${prefix}_ankle_link_b_to_${prefix}_ankle_link_c_1" type="continuous">
      <parent link="${prefix}_ankle_link_b"/>
      <child link="${prefix}_ankle_link_c_1"/>
      <axis rpy="0 0 0" xyz="0 0 1"/>
      <origin rpy="0 0 ${-pi/4}" xyz="${l_ankle_b} 0 0"/>
    </joint>

    <link name="${prefix}_ankle_link_c_2">
      <visual>
        <geometry>
          <cylinder length="${l_ankle_c2}" radius="0.003"/>
        </geometry>
        <origin rpy="0 ${pi/2} 0" xyz="${l_ankle_c2/2} 0 0"/>
        <material name="blue"/>
      </visual>
    </link>
    <joint name="${prefix}_ankle_link_c_1_to_${prefix}_ankle_link_c_2" type="prismatic">
      <limit lower="${-0.0515/2}" upper="${0.0515/2}" effort="1" velocity="1"/>
      <parent link="${prefix}_ankle_link_c_1"/>
      <child link="${prefix}_ankle_link_c_2"/>
      <axis rpy="0 0 0" xyz="1 0 0"/>
      <origin rpy="0 0 0" xyz="${0.0515/2} 0 0"/>
    </joint>

    <link name="${prefix}_foot_link_a">
      <visual>
        <geometry>
          <cylinder length="${l_foot_a}" radius="0.003"/>
        </geometry>
        <origin rpy="0 ${pi/2} 0" xyz="${l_foot_a/2} 0 0"/>
        <material name="blue"/>
      </visual>
    </link>
    <joint name="${prefix}_ankle_link_c_2_to_${prefix}_foot_link_a" type="continuous">
      <parent link="${prefix}_ankle_link_c_2"/>
      <child link="${prefix}_foot_link_a"/>
      <axis rpy="0 0 0" xyz="0 0 1"/>
      <origin rpy="0 0 ${-pi/2}" xyz="${l_ankle_c2} 0 0"/>
    </joint>

  </xacro:macro>



  <link name="base_link">
  </link>
  <xacro:leg prefix="right" reflect="1" />
  <xacro:leg prefix="left" reflect="-1" />




</robot>
